Workbook

Sheet Guide
A1: ALITI Syrine | F1: Selection de la classe | G1: MSI 5-25 DO A ISI PARIS
A2: BELKACEMI Cylia | F2: Nom du groupe | G2: BANZAI | K2: 0
A3: DANTU Nathan

Sheet MODE D'EMPLOI
A1: Mode d'emploi
A3: MASTERE DEV/DATA/CS/DO - Les Mastères CPIT sont sur une autre grille
A5: ONGLET DATA & RECAP
A6: 1. Indiquer le nom de la classe
A7: 2. Compléter la liste des étudiants
A8: 3. Reporter les notes des dossiers et vidéos dans la colonne adéquate
A10: EVAL DES GROUPES
A11: Dupliquer l'onglet "DOSSIER M1 GRP 1" ou "VIDEO M1 GRP1" en fonction du nombre de groupe en mastère 1
A12: Faire l'équivalent en Mastère 2 si vous corrigez des mastères 2
A13: Compléter les colonnes "points" en utilisant la liste déroulante
A14: Note de groupe
A15: Note individuelle
... A18: reportez ensuite sur les autres étudiants

Sheet DATA & RECAP
B2: Classe: | C2: *Indiquer le nom de classe
B3: *A compléter afin de récupérer la liste des étudiants dans les grilles
B4: ETUDIANTS | E4: NOTES | G4: TOTAL
B5: Groupe Projet | C5: Nom | D5: Prénom | E5: DOSSIER TECHNIQUE | F5: VIDEO | G5: DOSSIER & VIDEO
B6: Ref Péda | C6: HERROU | D6: Christophe | G6: =IFERROR(AVERAGE(E6:F6),"")
B7: Ref Péda | C7: NUNES | D7: Marc | G7: =IFERROR(AVERAGE(E7:F7),"")
B8: Ref Péda | C8: METRAL | D8: Jérôme | G8: =IFERROR(AVERAGE(E8:F8),"")
B9: Ref Péda | C9: GRAVELINE | D9: Timothée | G9: =IFERROR(AVERAGE(E9:F9),"")
G10: =IFERROR(AVERAGE(E10:F10),"")
G11: =IFERROR(AVERAGE(E11:F11),"")
G12: =IFERROR(AVERAGE(E12:F12),"")
G13: =IFERROR(AVERAGE(E13:F13),"")
G14: =IFERROR(AVERAGE(E14:F14),"")
G15: =IFERROR(AVERAGE(E15:F15),"")
G16: =IFERROR(AVERAGE(E16:F16),"")
G17: =IFERROR(AVERAGE(E17:F17),"")
G18: =IFERROR(AVERAGE(E18:F18),"")
G19: =IFERROR(AVERAGE(E19:F19),"")
G20: =IFERROR(AVERAGE(E20:F20),"")
G21: =IFERROR(AVERAGE(E21:F21),"")
... G32: =IFERROR(AVERAGE(E32:F32),"")

Sheet DOSSIER M1 GRP 1
B1: Note de groupe
B2: Note individuelle
C3: NOM GROUPE PROJET : | E3: REF PEDA | K3: Note de groupe
B4: MASTERE DEV/DATA/CS/DO - Les Mastères CPIT sont sur une autre grille | K4: Note individuelle
C5: Etudiant 1 | D5: Etudiant 2 | E5: Etudiant 3 | F5: Etudiant 4 | G5: Etudiant 5
B6: Management de projet
B7: Critères d'évaluation | C7: Points | K7: NOM | L7: Prénom | M7: NOTE DOSSIER TECHNIQUE
B8: Justification de la méthodologie de réalisation et d'organisation équipe (cohérence avec le projet) | C8: 5 | D8: 5 | E8: 5 | F8: 5 | G8: 5 | J8: Etudiant 1 | K8: HERROU | L8: =_xlfn.XLOOKUP(K8,'DATA & RECAP'!C6:C32,'DATA & RECAP'!D6:D32,"Sélectionnez un nom") -> Christophe | M8: =IFERROR(SUM(C10,C22,C41,C50,C57)*20/'DOSSIER TECHNIQUE M1'!C42,"") -> 20
B9: Commentaire | J9: Etudiant 3 | K9: METRAL | L9: Jérôme | M9: =IFERROR(SUM(D10,D22,D41,D50,D57)*20/'DOSSIER TECHNIQUE M1'!C42,"") -> 20
B10: Total : 5 points | C10: =SUM(C8:C8) -> 5 | D10: =SUM(D8:D8) -> 5 | E10: =SUM(E8:E8) -> 5 | F10: =SUM(F8:F8) -> 5 | G10: =SUM(G8:G8) -> 5 | J10: Etudiant 3 | K10: NUNES | L10: Marc | M10: =IFERROR(SUM(E10,E22,E41,E50,E57)*20/'DOSSIER TECHNIQUE M1'!C42,"") -> 20
J11: Etudiant 4 | K11: GRAVELINE | L11: Timothée | M11: =IFERROR(SUM(F10,F22,F41,F50,F57)*20/'DOSSIER TECHNIQUE M1'!C42,"") -> 20
B12: Planification détaillée | J12: Etudiant 5 | K12: GRAVELINE | L12: Timothée | M12: =IFERROR(SUM(G10,G22,G41,G50,G57)*20/'DOSSIER TECHNIQUE M1'!C42,"") -> 20
B13: Critères d'évaluation | C13: Points
B14: Cohérence de la planification globale (adéquation des étapes aux objectifs) | C14: 5 | D14: 5 | E14: 5 | F14: 5 | G14: 5
B15: Décomposition des tâches en sous-tâches détaillées (conception, développement, tests, déploiement) | C15: 5 | D15: 5 | E15: 5 | F15: 5 | G15: 5
B16: Clarté et précision du calendrier (dates de début, fin, durée des tâches) | C16: 5 | D16: 5 | E16: 5 | F16: 5 | G16: 5
B17: Gestion des dépendances entre les tâches (identification et gestion des relations entre les tâches) | C17: 5 | D17: 5 | E17: 5 | F17: 5 | G17: 5
B18: Gestion des risques identifiés (identification, évaluation et stratégies de mitigation) | C18: 5 | D18: 5 | E18: 5 | F18: 5 | G18: 5
B19: Utilisation d'outils de planification (diagramme de Gantt ou autre outil pertinent) | C19: 5 | D19: 5 | E19: 5 | F19: 5 | G19: 5
B20: Inclusion de jalons clés (milestones) pour valider les étapes importantes du projet | C20: 5 | D20: 5 | E20: 5 | F20: 5 | G20: 5
B21: Commentaire
B22: Total : 35 points | C22: =SUM(C14:C20) -> 35 | D22: =SUM(D14:D20) -> 35 | E22: =SUM(E14:E20) -> 35 | F22: =SUM(F14:F20) -> 35 | G22: =SUM(G14:G20) -> 35
B24: Solution Technique
B25: Critères d'évaluation | C25: Points
B26: Précision technique du livrable final (exactitude des informations techniques fournies) | C26: 10 | D26: 10 | E26: 10 | F26: 10 | G26: 10
B27: Cohérence de la solution proposée (pertinence des choix techniques par rapport aux objectifs) | C27: 10 | D27: 10 | E27: 10 | F27: 10 | G27: 10
B28: Qualité de la justification des choix techniques | C28: 10 | D28: 10 | E28: 10 | F28: 10 | G28: 10
B29: Mise place d'une politique de veille | C29: 2 | D29: 2 | E29: 2 | F29: 2 | G29: 2
B30: Innovation de la solution | C30: 2 | D30: 2 | E30: 2 | F30: 2 | G30: 2
B31: Cohérence du PRA/PCA | C31: 5 | D31: 5 | E31: 5 | F31: 5 | G31: 5
B32: Qualité des schémas techniques ou diagrammes inclus dans le livrable final. | C32: 5 | D32: 5 | E32: 5 | F32: 5 | G32: 5
B33: Rigueur des tests effectués sur le produit final (exhaustivité et qualité des résultats présentés) | C33: 5 | D33: 5 | E33: 5 | F33: 5 | G33: 5
B34: Integration de notions GreenIT | C34: 2 | D34: 2 | E34: 2 | F34: 2 | G34: 2
B35: Prise en compte des normes et obligations réglementaires | C35: 5 | D35: 5 | E35: 5 | F35: 5 | G35: 5
B36: Prise en compte des personnes en situation de handicap | C36: 2 | D36: 2 | E36: 2 | F36: 2 | G36: 2
B37: Documentation utilisateur fournie dans le livrable final (clarté et exhaustivité pour l’utilisateur final) | C37: 10 | D37: 10 | E37: 10 | F37: 10 | G37: 10
... B39: Gouvernance et vision d’évolution des systèmes : Inclusion d’une réflexion sur l’avenir de l’infrastructure ou des applications livrées, accompagnée d’une roadmap pour leur maintenance ou leur évolution. | C39: 5 | D39: 5 | E39: 5 | F39: 5 | G39: 5
B40: Commentaire
B41: Total : 78 points | C41: =SUM(C26:C39) -> 78 | D41: =SUM(D26:D39) -> 78 | E41: =SUM(E26:E39) -> 78 | F41: =SUM(F26:F39) -> 78 | G41: =SUM(G26:G39) -> 78
B43: Analyse dynamique projet
...

Sheet VIDEO M1 GRP 1
B1: Note de groupe
B2: Note individuelle
C3: NOM GROUPE PROJET : | E3: REF PEDA | K3: Note de groupe
B4: MASTERE DEV/DATA/CS/DO - Les Mastères CPIT sont sur une autre grille | K4: Note individuelle
C5: Etudiant 1 | D5: Etudiant 2 | E5: Etudiant 3 | F5: Etudiant 4 | G5: Etudiant 5
B6: Vidéo
B7: Critères d'évaluation | C7: Points | K7: NOM | L7: Prénom | M7: NOTE VIDEO
B8: Structure de la video | C8: 5 | D8: 5 | E8: 5 | F8: 5 | G8: 5 | J8: Etudiant 1 | K8: HERROU | L8: =_xlfn.XLOOKUP(K8,'DATA & RECAP'!C6:C32,'DATA & RECAP'!D6:D32,"Sélectionnez un nom") -> Christophe | M8: =IFERROR(SUM(C20)*20/'VIDEO M1 & M2'!$B$17,"") -> 20
B9: Contexte et objectifs du projet : Le groupe présente clairement sa compréhension globale du projet et expose les axes choisis pour traiter l’ensemble des enjeux. | C9: 10 | D9: 10 | E9: 10 | F9: 10 | G9: 10 | J9: Etudiant 2 | K9: METRAL | L9: Jérôme | M9: =IFERROR(SUM(D20)*20/'VIDEO M1 & M2'!$B$17,"") -> 20
B10: Qualité de la démonstration du MVP (fonctionnalités opérationnelles, adéquation aux attentes du projet) | C10: 10 | D10: 10 | E10: 10 | F10: 10 | G10: 10 | J10: Etudiant 3 | K10: NUNES | L10: Marc | M10: =IFERROR(SUM(E20)*20/'VIDEO M1 & M2'!$B$17,"") -> 20
B11: Qualité visuelle et technique de la vidéo (Esthétique, cohérence visuelle, et adéquation au discours.) | C11: 5 | D11: 5 | E11: 5 | F11: 5 | G11: 5 | J11: Etudiant 4 | K11: GRAVELINE | L11: Timothée | M11: =IFERROR(SUM(F20)*20/'VIDEO M1 & M2'!$B$17,"") -> 20
B12: Originalité des solutions proposées dans le MVP (innovation par rapport aux standards du marché ou aux attentes initiales) | C12: 2 | D12: 2 | E12: 2 | F12: 2 | G12: 2 | J12: Etudiant 5 | K12: GRAVELINE | L12: Timothée | M12: =IFERROR(SUM(G20)*20/'VIDEO M1 & M2'!$B$17,"") -> 20
B13: Impact potentiel du MVP : Capacité du projet à convaincre les utilisateurs finaux en répondant aux besoins réels. | C13: 10 | D13: 10 | E13: 10 | F13: 10 | G13: 10
B14: Aller plus loin que l'attendu : Capacité du projet à dépasser les attentes initiales et apporter une valeur ajoutée supplémentaire. | C14: 2 | D14: 2 | E14: 2 | F14: 2 | G14: 2
B15: Fluidité | C15: 5 | D15: 5 | E15: 5 | F15: 5 | G15: 5
B16: Pertinence des informations | C16: 5 | D16: 5 | E16: 5 | F16: 5 | G16: 5
B17: Capacité à capter l'attention | C17: 5 | D17: 5 | E17: 5 | F17: 5 | G17: 5
B18: Capacité à convaincre de la pertinance de la solution | C18: 5 | D18: 5 | E18: 5 | F18: 5 | G18: 5
B19: Commentaire
B20: Total : 64 points | C20: =SUM(C8:C18) -> 64 | D20: =SUM(D8:D18) -> 64 | E20: =SUM(E8:E18) -> 64 | F20: =SUM(F8:F18) -> 64 | G20: =SUM(G8:G18) -> 64

Sheet DOSSIER M2 GRP 1
B1: Note de groupe
B2: Note individuelle
C3: NOM GROUPE PROJET : | E3: REF PEDA | K3: Note de groupe
B4: MASTERE DEV/DATA/CS/DO - Les Mastères CPIT sont sur une autre grille | K4: Note individuelle
C5: Etudiant 1 | D5: Etudiant 2 | E5: Etudiant 3 | F5: Etudiant 4 | G5: Etudiant 5
B6: Management de projet
B7: Critères d'évaluation | C7: Points | K7: NOM | L7: Prénom | M7: NOTE DOSSIER TECHNIQUE
B8: Gestion des coûts cohérente avec les objectifs et contraintes de l'entreprise | C8: 10 | D8: 10 | E8: 10 | F8: 10 | G8: 10 | J8: Etudiant 1 | K8: HERROU | L8: =_xlfn.XLOOKUP(K8,'DATA & RECAP'!C6:C32,'DATA & RECAP'!D6:D32,"Sélectionnez un nom") -> Christophe | M8: =IFERROR(SUM(C11,C23,C43,C52,C59)*20/'DOSSIER TECHNIQUE M2'!C43,"") -> 20
B9: Justification de la méthodologie de réalisation et d'organisation équipe (cohérence avec le projet) | C9: 5 | D9: 5 | E9: 5 | F9: 5 | G9: 5 | J9: Etudiant 2 | K9: METRAL | L9: Jérôme | M9: =IFERROR(SUM(D11,D23,D43,D52,D59)*20/'DOSSIER TECHNIQUE M2'!C43,"") -> 20
B10: Commentaire | J10: Etudiant 3 | K10: GRAVELINE | L10: Timothée | M10: =IFERROR(SUM(F11,F23,F43,F52,F59)*20/'DOSSIER TECHNIQUE M2'!C43,"") -> 20
B11: Total : 15 points | C11: =SUM(C8:C9) -> 15 | D11: =SUM(D8:D9) -> 15 | E11: =SUM(E8:E9) -> 15 | F11: =SUM(F8:F9) -> 15 | G11: =SUM(G8:G9) -> 15 | J11: Etudiant 4 | K11: GRAVELINE | L11: Timothée | M11: =IFERROR(SUM(F11,F23,F43,F52,F59)*20/'DOSSIER TECHNIQUE M2'!C43,"") -> 20
J12: Etudiant 5 | K12: GRAVELINE | L12: Timothée | M12: =IFERROR(SUM(G11,G23,G43,G52,G59)*20/'DOSSIER TECHNIQUE M2'!C43,"") -> 20
B13: Planification détaillée
B14: Critères d'évaluation | C14: Points
B15: Cohérence de la planification globale (adéquation des étapes aux objectifs) | C15: 5 | D15: 5 | E15: 5 | F15: 5 | G15: 5
B16: Décomposition des tâches en sous-tâches détaillées (conception, développement, tests, déploiement) | C16: 5 | D16: 5 | E16: 5 | F16: 5 | G16: 5
B17: Clarté et précision du calendrier (dates de début, fin, durée des tâches) | C17: 5 | D17: 5 | E17: 5 | F17: 5 | G17: 5
B18: Gestion des dépendances entre les tâches (identification et gestion des relations entre les tâches) | C18: 5 | D18: 5 | E18: 5 | F18: 5 | G18: 5
B19: Gestion des risques identifiés (identification, évaluation et stratégies de mitigation) | C19: 5 | D19: 5 | E19: 5 | F19: 5 | G19: 5
B20: Utilisation d'outils de planification (diagramme de Gantt ou autre outil pertinent) | C20: 5 | D20: 5 | E20: 5 | F20: 5 | G20: 5
B21: Inclusion de jalons clés (milestones) pour valider les étapes importantes du projet | C21: 5 | D21: 5 | E21: 5 | F21: 5 | G21: 5
B22: Commentaire
B23: Total : 35 points | C23: =SUM(C15:C21) -> 35 | D23: =SUM(D15:D21) -> 35 | E23: =SUM(E15:E21) -> 35 | F23: =SUM(F15:F21) -> 35 | G23: =SUM(G15:G21) -> 35
B25: Solution Technique
B26: Critères d'évaluation | C26: Points
B27: Précision technique du livrable final (exactitude des informations techniques fournies) | C27: 10 | D27: 10 | E27: 10 | F27: 10 | G27: 10
B28: Cohérence de la solution proposée (pertinence des choix techniques par rapport aux objectifs) | C28: 10 | D28: 10 | E28: 10 | F28: 10 | G28: 10
B29: Qualité de la justification des choix techniques | C29: 10 | D29: 10 | E29: 10 | F29: 10 | G29: 10
B30: Mise place d'une politique de veille | C30: 2 | D30: 2 | E30: 2 | F30: 2 | G30: 2
B31: Innovation de la solution | C31: 2 | D31: 2 | E31: 2 | F31: 2 | G31: 2
B32: Mise en place d'une politique de veille (CPIT) | C32: 5 | D32: 5 | E32: 5 | F32: 5 | G32: 5
B33: Cohérence du PRA/PCA | C33: 10 | D33: 10 | E33: 10 | F33: 10 | G33: 10
B34: Rigueur des tests effectués sur le produit final (exhaustivité et qualité des résultats présentés) | C34: 5 | D34: 5 | E34: 5 | F34: 5 | G34: 5
B35: Integration de notions GreenIT | C35: 2 | D35: 2 | E35: 2 | F35: 2 | G35: 2
B36: Prise en compte des normes et obligations réglementaires | C36: 5 | D36: 5 | E36: 5 | F36: 5 | G36: 5
B37: Prise en compte des personnes en situation de handicap | C37: 2 | D37: 2 | E37: 2 | F37: 2 | G37: 2
B38: Qualité des schémas techniques ou diagrammes inclus dans le livrable final. | C38: 5 | D38: 5 | E38: 5 | F38: 5 | G38: 5
... B41: Gouvernance et vision d’évolution des systèmes : Inclusion d’une réflexion sur l’avenir de l’infrastructure ou des applications livrées, accompagnée d’une roadmap pour leur maintenance ou leur évolution. | C41: 10 | D41: 10 | E41: 10 | F41: 10 | G41: 10
B42: Commentaire
B43: Total : 93 points | C43: =SUM(C27:C41) -> 93 | D43: =SUM(D27:D41) -> 93 | E43: =SUM(E27:E41) -> 93 | F43: =SUM(F27:F41) -> 93 | G43: =SUM(G27:G41) -> 93
...

Sheet VIDEO M2 GRP1
B1: Note de groupe
B2: Note individuelle
C3: NOM GROUPE PROJET : | E3: REF PEDA | K3: Note de groupe
B4: MASTERE DEV/DATA/CS/DO - Les Mastères CPIT sont sur une autre grille | K4: Note individuelle
C5: Etudiant 1 | D5: Etudiant 2 | E5: Etudiant 3 | F5: Etudiant 4 | G5: Etudiant 5
B6: Vidéo
B7: Critères d'évaluation | C7: Points | K7: NOM | L7: Prénom | M7: NOTE VIDEO
B8: Structure de la video | C8: 5 | D8: 5 | E8: 5 | F8: 5 | G8: 5 | J8: Etudiant 1 | K8: HERROU | L8: =_xlfn.XLOOKUP(K8,'DATA & RECAP'!C6:C32,'DATA & RECAP'!D6:D32,"Sélectionnez un nom") -> Christophe | M8: =IFERROR(SUM(C20)*20/'VIDEO M1 & M2'!$B$17,"") -> 20
B9: Contexte et objectifs du projet : Le groupe présente clairement sa compréhension globale du projet et expose les axes choisis pour traiter l’ensemble des enjeux. | C9: 10 | D9: 10 | E9: 10 | F9: 10 | G9: 10 | J9: Etudiant 2 | K9: METRAL | L9: Jérôme | M9: =IFERROR(SUM(D20)*20/'VIDEO M1 & M2'!$B$17,"") -> 20
B10: Qualité de la démonstration du MVP (fonctionnalités opérationnelles, adéquation aux attentes du projet) | C10: 10 | D10: 10 | E10: 10 | F10: 10 | G10: 10 | J10: Etudiant 3 | K10: NUNES | L10: Marc | M10: =IFERROR(SUM(E20)*20/'VIDEO M1 & M2'!$B$17,"") -> 20
B11: Qualité visuelle et technique de la vidéo (Esthétique, cohérence visuelle, et adéquation au discours.) | C11: 5 | D11: 5 | E11: 5 | F11: 5 | G11: 5 | J11: Etudiant 4 | K11: GRAVELINE | L11: Timothée | M11: =IFERROR(SUM(F20)*20/'VIDEO M1 & M2'!$B$17,"") -> 20
B12: Originalité des solutions proposées dans le MVP (innovation par rapport aux standards du marché ou aux attentes initiales) | C12: 2 | D12: 2 | E12: 2 | F12: 2 | G12: 2 | J12: Etudiant 5 | K12: GRAVELINE | L12: Timothée | M12: =IFERROR(SUM(G20)*20/'VIDEO M1 & M2'!$B$17,"") -> 20
B13: Impact potentiel du MVP : Capacité du projet à convaincre les utilisateurs finaux en répondant aux besoins réels. | C13: 10 | D13: 10 | E13: 10 | F13: 10 | G13: 10
B14: Aller plus loin que l'attendu : Capacité du projet à dépasser les attentes initiales et apporter une valeur ajoutée supplémentaire. | C14: 2 | D14: 2 | E14: 2 | F14: 2 | G14: 2
B15: Fluidité | C15: 5 | D15: 5 | E15: 5 | F15: 5 | G15: 5
B16: Pertinence des informations | C16: 5 | D16: 5 | E16: 5 | F16: 5 | G16: 5
B17: Capacité à capter l'attention | C17: 5 | D17: 5 | E17: 5 | F17: 5 | G17: 5
B18: Capacité à convaincre de la pertinance de la solution | C18: 5 | D18: 5 | E18: 5 | F18: 5 | G18: 5
B19: Commentaire
B20: Total : 64 points | C20: =SUM(C8:C18) -> 64 | D20: =SUM(D8:D18) -> 64 | E20: =SUM(E8:E18) -> 64 | F20: =SUM(F8:F18) -> 64 | G20: =SUM(G8:G18) -> 64

Sheet DOSSIER TECHNIQUE M1
B1: Notation solo
B2: Notation groupe
C3: PTS MAX | D3: Blocs 40147 | E3: Blocs 40165 cyber | F3: Blocs 40165 devops | G3: Blocs 40166 Dev | H3: Blocs 40167 Data | I3: Blocs 40168 CPIT
A4: Management de projet
B5: Justification de la méthodologie de réalisation et d'organisation équipe (cohérence avec le projet) | C5: 5 | D5: BC01 | E5: 2 | F5: 2 | G5: 2 | H5: 2 | I5: 3
B6: Programme de conduite du changement cohérent et argumenté (CPIT) | C6: 5 | D6: BC03 | I6: 1
A7: Planification détaillée
B8: Cohérence de la planification globale (adéquation des étapes aux objectifs) | C8: 5 | D8: BC01 | E8: 2 | F8: 2 | G8: 4 | H8: 2 | I8: 2
B9: Décomposition des tâches en sous-tâches détaillées (conception, développement, tests, déploiement) | C9: 5 | D9: BC01 | E9: 2 | F9: 2 | G9: 4 | H9: 2 | I9: 2
B10: Clarté et précision du calendrier (dates de début, fin, durée des tâches) | C10: 5 | D10: BC01 | E10: 2 | F10: 2 | G10: 4 | H10: 2 | I10: 2
B11: Gestion des dépendances entre les tâches (identification et gestion des relations entre les tâches) | C11: 5 | D11: BC01 | E11: 2 | F11: 2 | G11: 4 | H11: 2 | I11: 2
B12: Gestion des risques identifiés (identification, évaluation et stratégies de mitigation) | C12: 5 | D12: BC02 | E12: 2 | F12: 2 | G12: 4 | H12: 2 | I12: 2
B13: Utilisation d'outils de planification (diagramme de Gantt ou autre outil pertinent) | C13: 5 | D13: BC01 | E13: 2 | F13: 2 | G13: 4 | H13: 2 | I13: 2
B14: Inclusion de jalons clés (milestones) pour valider les étapes importantes du projet | C14: 5 | D14: BC01 | E14: 2 | F14: 2 | G14: 4 | H14: 2 | I14: 2
A15: Solution Technique
B16: Précision technique du livrable final (exactitude des informations techniques fournies) | C16: 10 | D16: BC03/BC04 sauf CPIT | E16: 4 | F16: 5 | G16: 3 | H16: 4 | I16: --
B17: Cohérence de la solution proposée (pertinence des choix techniques par rapport aux objectifs) | C17: 10 | D17: BC03/BC04 | E17: 4 | F17: 5 | G17: 3 | H17: 4 | I17: 4
B18: Qualité de la justification des choix techniques | C18: 10 | D18: BC01 | E18: 4 | F18: 5 | G18: 3 | H18: 2 | I18: 4
B19: Mise place d'une politique de veille | C19: 2 | D19: BC01 | E19: 1 | F19: 1 | G19: 1 | H19: 1 | I19: 1
B20: Innovation de la solution | C20: 2 | D20: BC01 | E20: 1 | F20: 1 | G20: 1 | H20: 1 | I20: 1
B21: Cohérence du PRA/PCA | C21: 5 | D21: BC02 sauf CPIT | E21: 3 | F21: 3 | G21: 5 | H21: 3 | I21: --
B22: Documentation utilisateur fournie dans le livrable final (clarté et exhaustivité pour l’utilisateur final) | C22: 10 | D22: 2 | E22: 2 | F22: 2 | G22: 2 | H22: 2 | I22: 3
B23: Rigueur des tests effectués sur le produit final (exhaustivité et qualité des résultats présentés) | C23: 5 | D23: BC03/BC04 | E23: 3 | F23: 3 | G23: 5 | H23: 5 | I23: 3
B24: Integration de notions GreenIT | C24: 2 | D24: BC02 | E24: 1 | F24: 1 | G24: 1 | H24: 1 | I24: 1
B25: Prise en compte des normes et obligations réglementaires | C25: 5 | D25: BC02 | E25: 3 | F25: 3 | G25: 5 | H25: 2 | I25: 1
B26: Prise en compte des personnes en situation de handicap | C26: 2 | D26: BC02 | E26: 3 | F26: 3 | G26: 5 | H26: 3 | I26: 1
B27: Inclusion d’une analyse critique sur les limites techniques rencontrées durant le projet. | C27: 5 | D27: BC03/BC04 | E27: 4 | F27: 5 | G27: 1 | H27: 1 | I27: 4
B28: Qualité des schémas techniques ou diagrammes inclus dans le livrable final. | C28: 5 | D28: BC03/BC04 | E28: 1 | F28: 1 | G28: 5 | H28: 2 | I28: 3
B29: Gouvernance et vision d’évolution des systèmes : Inclusion d’une réflexion sur l’avenir de l’infrastructure ou des applications livrées, accompagnée d’une roadmap pour leur maintenance ou leur évolution. | C29: 5 | D29: BC02 | E29: 4 | F29: 5 | G29: 1 | H29: 5 | I29: 4
A30: Analyse dynamique projet
B31: Réflexion personnelle sur les défis rencontrés | C31: 2 | D31: BC02 | E31: 2 | F31: 2 | G31: 2 | H31: 2 | I31: 3
B32: Capacité à identifier ses forces et faiblesses | C32: 2 | D32: BC02 | E32: 2 | F32: 2 | G32: 2 | H32: 2 | I32: 3
B33: Analyse des compétences développées | C33: 2 | D33: BC02 | E33: 2 | F33: 2 | G33: 2 | H33: 2 | I33: 3
B34: Proposition d'axes d'amélioration pour de futurs projets | C34: 2 | D34: BC02 | E34: 1 | F34: 1 | G34: 1 | H34: 2 | I34: 2
A35: Respect du cadre
B36: Professionnalisme du livrable final soumis (présentation générale, organisation, mise en page) | C36: 10 | D36: BC01 | E36: 1 | F36: 1 | G36: 2 | H36: 2 | I36: 2
D37: (3/4 selon l'option)
A38: Bonus | B38: Le groupe est allé au-delà des demandes et/ou a intégré les propositions bonus | C38: 5 | D38: -- | E38: -- | F38: -- | G38: -- | H38: -- | I38: --
A39: Rendu du dossier : Un fichier Zip contenant un rendu par membre du groupe. Nomenclature du zip : PE_2526_codepromo(ex : M1DEVA)_nometudiant1_nometudiant2_nom(etc…).zip Nomenclature des documents apprenants : PE-2526_codepromo_NomPrenomEtudiant.pdf
A40: Plan
...

Sheet DOSSIER TECHNIQUE M2
B1: Notation solo
B2: Notation groupe
C3: PTS MAX | D3: Blocs 40147 | E3: Blocs 40165 cyber | F3: Blocs 40165 devops | G3: Blocs 40166 Dev | H3: Blocs 40167 Data | I3: Blocs 40168 CPIT
A4: Management de projet
B5: Gestion des coûts cohérente avec les objectifs et contraintes de l'entreprise | C5: 10 | D5: BC01 | E5: 2 | F5: 2 | G5: 1 | H5: 2 | I5: 2
B6: Justification de la méthodologie de réalisation et d'organisation équipe (cohérence avec le projet) | C6: 5 | D6: BC01 | E6: 2 | F6: 2 | G6: 2 | H6: 2 | I6: 3
B7: Programme de conduite du changement cohérent et argumenté (CPIT) | C7: 10 | D7: BC03 | I7: 1
A8: Planification détaillée
B9: Cohérence de la planification globale (adéquation des étapes aux objectifs) | C9: 5 | D9: BC01 | E9: 2 | F9: 2 | G9: 4 | H9: 2 | I9: 2
B10: Décomposition des tâches en sous-tâches détaillées (conception, développement, tests, déploiement) | C10: 5 | D10: BC01 | E10: 2 | F10: 2 | G10: 4 | H10: 2 | I10: 2
B11: Clarté et précision du calendrier (dates de début, fin, durée des tâches) | C11: 5 | D11: BC01 | E11: 2 | F11: 2 | G11: 4 | H11: 2 | I11: 2
B12: Gestion des dépendances entre les tâches (identification et gestion des relations entre les tâches) | C12: 5 | D12: BC01 | E12: 2 | F12: 2 | G12: 4 | H12: 2 | I12: 2
B13: Gestion des risques identifiés (identification, évaluation et stratégies de mitigation) | C13: 5 | D13: BC02 | E13: 2 | F13: 2 | G13: 4 | H13: 2 | I13: 2
B14: Utilisation d'outils de planification (diagramme de Gantt ou autre outil pertinent) | C14: 5 | D14: BC01 | E14: 2 | F14: 2 | G14: 4 | H14: 2 | I14: 2
B15: Inclusion de jalons clés (milestones) pour valider les étapes importantes du projet | C15: 5 | D15: BC01 | E15: 2 | F15: 2 | G15: 4 | H15: 2 | I15: 2
A16: Solution Technique
B17: Précision technique du livrable final (exactitude des informations techniques fournies) | C17: 10 | D17: BC03/BC04 sauf CPIT | E17: 4 | F17: 5 | G17: 3 | H17: 4 | I17: --
B18: Cohérence de la solution proposée (pertinence des choix techniques par rapport aux objectifs) | C18: 10 | D18: BC03/BC04 | E18: 4 | F18: 5 | G18: 3 | H18: 4 | I18: 4
B19: Qualité de la justification des choix techniques | C19: 10 | D19: BC01 | E19: 4 | F19: 5 | G19: 3 | H19: 2 | I19: 4
B20: Mise place d'une politique de veille | C20: 2 | D20: BC01 | E20: 1 | F20: 1 | G20: 1 | H20: 1 | I20: 1
B21: Innovation de la solution | C21: 2 | D21: BC01 | E21: 1 | F21: 1 | G21: 1 | H21: 1 | I21: 1
B22: Mise en place d'une politique de veille (CPIT) | C22: 5
B23: Cohérence du PRA/PCA | C23: 10 | D23: BC02 sauf CPIT | E23: 3 | F23: 3 | G23: 5 | H23: 3 | I23: --
B24: Documentation utilisateur fournie dans le livrable final (clarté et exhaustivité pour l’utilisateur final) | C24: 10 | D24: 2 | E24: 2 | F24: 2 | G24: 2 | H24: 2 | I24: 3
B25: Rigueur des tests effectués sur le produit final (exhaustivité et qualité des résultats présentés) | C25: 5 | D25: BC03/BC04 | E25: 3 | F25: 3 | G25: 5 | H25: 5 | I25: 3
B26: Integration de notions GreenIT | C26: 2 | D26: BC02 | E26: 1 | F26: 1 | G26: 1 | H26: 1 | I26: 1
B27: Prise en compte des normes et obligations réglementaires | C27: 5 | D27: BC02 | E27: 3 | F27: 3 | G27: 5 | H27: 2 | I27: 1
B28: Prise en compte des personnes en situation de handicap | C28: 2 | D28: BC02 | E28: 3 | F28: 3 | G28: 5 | H28: 3 | I28: 1
B29: Inclusion d’une analyse critique sur les limites techniques rencontrées durant le projet. | C29: 5 | D29: BC03/BC04 | E29: 4 | F29: 5 | G29: 1 | H29: 1 | I29: 4
B30: Qualité des schémas techniques ou diagrammes inclus dans le livrable final. | C30: 10 | D30: BC03/BC04 | E30: 1 | F30: 1 | G30: 5 | H30: 2 | I30: 3
B31: Gouvernance et vision d’évolution des systèmes : Inclusion d’une réflexion sur l’avenir de l’infrastructure ou des applications livrées, accompagnée d’une roadmap pour leur maintenance ou leur évolution. | C31: 5 | D31: BC02 | E31: 4 | F31: 5 | G31: 1 | H31: 5 | I31: 4
A32: Analyse dynamique projet
B33: Réflexion personnelle sur les défis rencontrés | C33: 2 | D33: BC02 | E33: 2 | F33: 2 | G33: 2 | H33: 2 | I33: 3
B34: Capacité à identifier ses forces et faiblesses | C34: 2 | D34: BC02 | E34: 2 | F34: 2 | G34: 2 | H34: 2 | I34: 3
B35: Analyse des compétences développées | C35: 2 | D35: BC02 | E35: 2 | F35: 2 | G35: 2 | H35: 2 | I35: 3
B36: Proposition d'axes d'amélioration pour de futurs projets | C36: 2 | D36: BC02 | E36: 1 | F36: 1 | G36: 1 | H36: 2 | I36: 2
A37: Respect du cadre
B38: Professionnalisme du livrable final soumis (présentation générale, organisation, mise en page) | C38: 10 | D38: BC01 | E38: 1 | F38: 1 | G38: 2 | H38: 2 | I38: 2
D39: (3/4 selon l'option)
A40: Bonus | B40: Le groupe est allé au-delà des demandes et/ou a intégré les propositions bonus | C40: 5 | D40: -- | E40: -- | F40: -- | G40: -- | H40: -- | I40: --
...

Sheet VIDEO M1 & M2
A1: Notation solo
A2: Notation groupe
B3: PTS MAX | C3: Blocs 40147 | D3: Blocs 40165 cyber | E3: Blocs 40165 devops | F3: Blocs 40166 Dev | G3: Blocs 40167 Data | H3: Blocs 40168 CPIT
A5: Structure de la video | B5: 5 | C5: 1 | D5: 1 | E5: 1 | F5: 2 | G5: 1 | H5: 3
A6: Fluidité | B6: 5 | C6: 1 | D6: 1 | E6: 1 | F6: 2 | G6: 2 | H6: 3
A7: Pertinence des informations | B7: 5 | C7: 1 | D7: 1 | E7: 1 | F7: 2 | G7: 1 | H7: 3
A8: Capacité à capter l'attention | B8: 5 | C8: 1 | D8: 1 | E8: 1 | F8: 2 | G8: 2 | H8: 3
A9: Capacité à convaincre de la pertinance de la solution | B9: 5 | C9: 1 | D9: 1 | E9: 1 | F9: 2 | G9: 1 | H9: 3
A10: Contexte et objectifs du projet : Le groupe présente clairement sa compréhension globale du projet et expose les axes choisis pour traiter l’ensemble des enjeux. | B10: 10 | C10: 3/4 | D10: 1 | E10: 1 | F10: 2 | G10: 5 | H10: 4
A11: Qualité de la démonstration du MVP (fonctionnalités opérationnelles, adéquation aux attentes du projet) | B11: 10 | C11: 3/4 | D11: 1 | E11: 1 | F11: 2 | G11: 1 | H11: 3
A12: Qualité visuelle et technique de la vidéo (Esthétique, cohérence visuelle, et adéquation au discours.) | B12: 5 | C12: 1 | D12: 1 | E12: 1 | F12: 2 | G12: 1 | H12: 3
A13: Originalité des solutions proposées dans le MVP (innovation par rapport aux standards du marché ou aux attentes initiales) | B13: 2 | C13: 1 | D13: 1 | E13: 1 | F13: 2 | G13: 4 | H13: 1
A14: Impact potentiel du MVP : Capacité du projet à convaincre les utilisateurs finaux en répondant aux besoins réels. | B14: 10 | C14: 2 | D14: 4 | E14: 5 | F14: 3 | G14: 2 | H14: 1
A15: Aller plus loin que l'attendu : Capacité du projet à dépasser les attentes initiales et apporter une valeur ajoutée supplémentaire. | B15: 2 | C15: 1 | D15: 4 | E15: 5 | F15: 4 | G15: 2 | H15: 4
B16: TOTAL
B17: =SUM(B5:B15) -> 64
A18: Rendu de la video en groupe, avec identification claire des parties de chacun. Incrustation video de la personne qui présente et affichage de son nom Elle est un support de présentation du dossier technique, qui sera remis au client Rendu du dossier : Solution 1 Un fichier Zip contenant la video du groupe. Nomenclature du zip : PE_2526_codepromo(ex : M1DEVA)_nometudiant1_nometudiant2_nom(etc…).zip Nomenclature de la video : PE-2526_codepromo_NomPrenomEtudiant.mp4 OU Solution 2 Un document TXT contenant le lien vers la video du groupe. A heberger sur youtube en mode Non Répertoriée. Toute autre plateforme ne sera pas validée. Nomenclature du document : PE_2526_codepromo(ex : M1DEVA)_nometudiant1_nometudiant2_nom(etc…).txt | C18: Plan : - Présentation de l'entreprise et de l'équipe projet - Analyse de la problématique et introduction à la solution proposée - Organisation et méthodologies appliquées - Présentation de la solution technique
A46: NOTE TOTALE DU BLOC 1
A47: NOTE TOTALE DU BLOC 2
A48: NOTE TOTALE
C51: =#REF!+#REF! -> #REF!
C52: =((#REF!*#REF!)+(#REF!*#REF!))*2 -> #REF!
C53: =(((C$51*20)/100)+(C52*80/100))/5 -> #REF!

Sheet Blocs et Competences
A1: BLOCS ISITECH 40147 | B1: Compétences mises en œuvre dans le cadre du projet d'étude
A2: BC01 - Manager, gérer et conduire des projets informatiques | B2: Élaborer un modèle financier complet pour prendre en compte les coûts de développement et les sources de revenus du projet informatique.
B3: Identifier les étapes clés de formation d'un projet et définir les objectifs et les acteurs impliqués, en utilisant des méthodes adaptées de gestion de projet afin d’organiser et coordonner sa progression efficace.
B4: Concevoir les budgets nécessaires à la réalisation du projet, évaluer sa rentabilité financière, et prendre en compte les aspects contractuels et juridiques pour garantir sa conformité.
B5: Évaluer les risques inhérents au projet et choisir une méthodologie de réalisation adaptée, en mettant en place des outils pratiques pour les anticiper et les gérer efficacement.
B6: Identifier et suivre la méthodologie du modèle de gestion de projet (agile, scrum, cascade, en V), en planifiant avec précision les différentes étapes, en garantissant un suivi minutieux des jalons et en gérant la livraison conforme des livrables prévus afin de maintenir une progression efficace et cohérente du projet.
B7: Établir une communication claire et transparente avec les différents acteurs impliqués, en tenant compte des personnes en situation de handicap et en favorisant la collaboration et en assurant une compréhension mutuelle des objectifs et des enjeux, afin de garantir la réalisation des objectifs définis par l'entreprise en matière de gestion des leads.
A8: BC02 - Auditer et piloter la stratégie du système d'information | B8: Réaliser un audit du système d'information en utilisant des méthodologies telles que l'analyse des risques, dans le but d'identifier les vulnérabilités et les menaces du système d’information.
B9: Mettre en place des processus et des systèmes de contrôle afin de garantir le respect des réglementations et des normes à utiliser
B10: Concevoir des plans détaillés qui spécifient les actions à entreprendre en cas d'incident majeur, en utilisant des procédures en cas de sinistre pour assurer la continuité opérationnelle du système d’information en tenant compte des personnes en situation de handicap
B11: Développer une vision stratégique alignée sur les objectifs organisationnels, en identifiant les besoins en matière de système d'information et en définissant des orientations stratégiques pour soutenir la croissance et l'innovation de l'entreprise
B12: Superviser et coordonner toutes les activités nécessaires à la mise en œuvre de la stratégie du système d'information, en tenant compte des personnes en situation de handicap, en assurant l'alignement avec les objectifs organisationnels, en supervisant les projets et initiatives clés, en coordonnant les ressources et en surveillant les performances pour garantir la réalisation des bénéfices attendus et l'atteinte des objectifs stratégiques.
A13: BC03 - (option) Concevoir et mettre en œuvre un système d’information sécurisé, virtuel et cloud | B13: Concevoir les architectures réseaux d'entreprises en utilisant des outils de gestion et de surveillance réseau et en respectant les normes en vigueur dans le but d'assurer leur fonctionnement optimal et garantir la sécurité des communications
B14: Concevoir et implémenter la sécurité des données et des périphériques sur le réseau afin de garantir leur intégrité en utilisant des dispositifs de protection.
B15: Surveiller et analyser les menaces de cybersécurité afin de détecter les intrusions en respectant la politiques et les procédures de sécurité de l’entreprise.
B16: Mettre en œuvre et surveiller des solutions de sécurité robustes hébergées sur le cloud en utilisant des techniques de gestion des identités et des accès (Authentification multifactorielle, gestion des clés et des certificats) pour protéger les données, les applications et les infrastructures de l’entreprise.
B17: Concevoir et déployer des postes de travail virtuels basés sur des systèmes d’exploitation professionnel, en tenant compte des personnes en situation de handicap, en utilisant des concepts avancés de virtualisation de bureau, afin d'améliorer la flexibilité opérationnelle, renforcer la sécurité des données et simplifier la gestion des ressources informatiques de l'entreprise.
B18: Concevoir, et mettre en œuvre une architecture virtualisée hautement disponible, en intégrant des politiques de sauvegarde et de restauration appropriées pour garantir la résilience de l'infrastructure informatique face aux incidents et aux pannes.
B19: Automatiser le déploiement et la gestion d'infrastructures informatiques à l'aide d’outils Infrastructure as Code (IaC), en développant des scripts et des configurations pour orchestrer efficacement les ressources cloud et on-premises, afin d'améliorer l'agilité opérationnelle et la scalabilité des environnements IT.
B20: Gérer l'ensemble du cycle de vie des infrastructures informatiques, depuis la configuration et l'administration avancée des systèmes jusqu'à la conception et la mise en œuvre de solutions distribuées, en utilisant des technologies basées sur des conteneurs d'applications logiciel afin d'assurer la disponibilité des services déployés sur des environnements complexes et hétérogènes.
A21: BC04 - (option) Concevoir et développer des solutions logicielles avancées, big data et intelligence artificielle | B21: Mettre en œuvre des techniques avancées de programmation, en explorant les concepts de gestion des erreurs, de manipulation avancée de données, de programmation orientée objet et de conception de modules personnalisés, afin de développer des solutions logicielles robustes et efficaces pour des applications avancées
B22: Acquérir une expertise sur le développement web, en explorant les concepts avancés d’un framework, afin de concevoir et de développer des applications web dynamiques et performantes.
B23: Maîtriser l'utilisation d’un language de programmation pour le Data Mining et l'Intelligence Artificielle, en explorant les concepts avancés de manipulation de données, de modélisation statistique et d'implémentation d'algorithmes d'apprentissage automatique, afin de développer des solutions efficaces pour l'analyse de données et la création de modèles prédictifs.
B24: Appliquer les concepts avancés de l'intelligence artificielle (IA), en explorant les algorithmes d'apprentissage automatique, les réseaux neuronaux profonds et les techniques de traitement du langage naturel, afin de concevoir et de développer des solutions innovantes pour résoudre des problèmes complexes dans divers domaines.
B25: Analyser les données massives à l'aide des techniques de Data Mining et d'Intelligence Artificielle dans le contexte du Big Data, en explorant les méthodes de clustering et de classification, ainsi que les outils de traitement de données distribuées, afin d'extraire des informations précieuses et de prendre des décisions stratégiques basées sur les données.
B26: Concevoir des solutions d'indexation, de stockage et de recherche de volumes importants de données non structurées, dans le but de fournir des résultats de recherche rapides et précis pour les utilisateurs finaux.
B27: Concevoir et mettre en œuvre des entrepôts de données (Datawarehouse) en utilisant des techniques de modélisation dimensionnelle, dans le but de centraliser, organiser et analyser efficacement de grandes quantités de données pour prendre des décisions stratégiques éclairées.
B28: Implémenter des techniques avancées d'exploitation de données, en utilisant des fonctions analytiques, des jointures complexes et des sous-requêtes imbriquées, dans le but d'extraire des informations pertinentes et d'effectuer des analyses approfondies sur de grands ensembles de données.
B29: Implémenter les bonnes pratiques d'ITIL orientées développement, en analysant les processus et les workflows existants, en concevant des méthodes efficaces de gestion des incidents, des changements et des versions dans le cycle de vie du développement logiciel, dans le but d'optimiser la qualité et la fiabilité des applications déployées.
B30: Appliquer les principes de la cybersécurité dans le contexte du web, en analysant les vulnérabilités, en mettant en œuvre des mesures de protection avancées, dans le but de sécuriser efficacement les applications et les données en ligne.
B31: Implémenter les principes d'intégration et de déploiement continu dans le cadre d'un projet d'applications web, en automatisant les étapes de compilation, de test et de déploiement, dans le but d'assurer une livraison rapide, fiable et itérative de nouvelles fonctionnalités aux utilisateurs finaux.

Sheet Pts évalués par blocs
B1: BC1 | C1: BC2 | D1: BC 3/4 (40147) | E1: BC3 | F1: BC4 | G1: BC5
A2: 40147 | B2: =COUNTIFS('DOSSIER TECHNIQUE M2'!$D$5:$D$38,1)+COUNTIFS('VIDEO M1 & M2'!$C$5:$C$15,1) -> 8 | C2: =COUNTIFS('DOSSIER TECHNIQUE M2'!$D5:$D38,2)+COUNTIFS('VIDEO M1 & M2'!$C5:$C15,2) -> 2 | D2: =COUNTIFS('DOSSIER TECHNIQUE M2'!$D5:$D38,"3/4")+COUNTIFS('VIDEO M1 & M2'!$C5:$C15,"3/4") -> 2 | E2: =COUNTIFS('DOSSIER TECHNIQUE M2'!$D5:$D38,"3")+COUNTIFS('VIDEO M1 & M2'!$C5:$C15,"3") -> 0
A3: Blocs 40165 cyber | B3: =COUNTIFS('DOSSIER TECHNIQUE M2'!$E$5:$E$38,1)+COUNTIFS('VIDEO M1 & M2'!$D$5:$D$15,1) -> 15 | C3: =COUNTIFS('DOSSIER TECHNIQUE M2'!$E$5:$E$38,2)+COUNTIFS('VIDEO M1 & M2'!$D$5:$D$15,2) -> 13 | E3: =COUNTIFS('DOSSIER TECHNIQUE M2'!$E$5:$E$38,3)+COUNTIFS('VIDEO M1 & M2'!$D$5:$D$15,3) -> 4 | F3: =COUNTIFS('DOSSIER TECHNIQUE M2'!$E$5:$E$38,4)+COUNTIFS('VIDEO M1 & M2'!$D$5:$D$15,4) -> 7
A4: Blocs 40165 devops | B4: =COUNTIFS('DOSSIER TECHNIQUE M2'!$F$5:$F$38,1)+COUNTIFS('VIDEO M1 & M2'!$E$5:$E$15,1) -> 15 | C4: =COUNTIFS('DOSSIER TECHNIQUE M2'!$F$5:$F$38,2)+COUNTIFS('VIDEO M1 & M2'!$E$5:$E$15,2) -> 13 | E4: =COUNTIFS('DOSSIER TECHNIQUE M2'!$F$5:$F$38,3)+COUNTIFS('VIDEO M1 & M2'!$E$5:$E$15,3) -> 4 | G4: =COUNTIFS('DOSSIER TECHNIQUE M2'!$F$5:$F$38,5)+COUNTIFS('VIDEO M1 & M2'!$E$5:$E$15,5) -> 7
A5: Blocs 40166 Dev | B5: =COUNTIFS('DOSSIER TECHNIQUE M2'!$G$5:$G$38,1)+COUNTIFS('VIDEO M1 & M2'!$F$5:$F$15,1) -> 7 | C5: =COUNTIFS('DOSSIER TECHNIQUE M2'!$G$5:$G$38,1)+COUNTIFS('VIDEO M1 & M2'!$F$5:$F$15,1) -> 7 | E5: =COUNTIFS('DOSSIER TECHNIQUE M2'!$G$5:$G$38,3)+COUNTIFS('VIDEO M1 & M2'!$F$5:$F$15,3) -> 4 | F5: =COUNTIFS('DOSSIER TECHNIQUE M2'!$G$5:$G$38,4)+COUNTIFS('VIDEO M1 & M2'!$F$5:$F$15,4) -> 8 | G5: =COUNTIFS('DOSSIER TECHNIQUE M2'!$G$5:$G$38,5)+COUNTIFS('VIDEO M1 & M2'!$F$5:$F$15,5) -> 5
A6: Blocs 40167 Data | B6: =COUNTIFS('DOSSIER TECHNIQUE M2'!$H$5:$H$38,1)+COUNTIFS('VIDEO M1 & M2'!$G$5:$G$15,1) -> 9 | C6: =COUNTIFS('DOSSIER TECHNIQUE M2'!$H$5:$H$38,2)+COUNTIFS('VIDEO M1 & M2'!$G$5:$G$15,2) -> 22 | E6: =COUNTIFS('DOSSIER TECHNIQUE M2'!$H$5:$H$38,3)+COUNTIFS('VIDEO M1 & M2'!$G$5:$G$15,3) -> 2 | F6: =COUNTIFS('DOSSIER TECHNIQUE M2'!$H$5:$H$38,4)+COUNTIFS('VIDEO M1 & M2'!$G$5:$G$15,4) -> 3 | G6: =COUNTIFS('DOSSIER TECHNIQUE M2'!$H$5:$H$38,5)+COUNTIFS('VIDEO M1 & M2'!$G$5:$G$15,5) -> 3
A7: Blocs 40168 CPIT | B7: =COUNTIFS('DOSSIER TECHNIQUE M2'!$I$5:$I$38,1)+COUNTIFS('VIDEO M1 & M2'!$H$5:$H$15,1) -> 8 | C7: =COUNTIFS('DOSSIER TECHNIQUE M2'!$I$5:$I$38,2)+COUNTIFS('VIDEO M1 & M2'!$H$5:$H$15,2) -> 10 | E7: =COUNTIFS('DOSSIER TECHNIQUE M2'!$I$5:$I$38,3)+COUNTIFS('VIDEO M1 & M2'!$H$5:$H$15,3) -> 14 | F7: =COUNTIFS('DOSSIER TECHNIQUE M2'!$I$5:$I$38,4)+COUNTIFS('VIDEO M1 & M2'!$H$5:$H$15,4) -> 6

Sheet Pour rappel - 2425
D2: isitech | E2: emineo | F2: NOM
F3: CLASSE
A4: Premier rendu : Analyse du sujet (N+1 MOIS) | F4: NIVEAU | G4: M1
A6: Critères d'évaluation | B6: Points | C6: Points MAX
A7: Qualité des questions (logique, pertinence, clarté) | B7: 5 | C7: 10 | D7: 0
A8: Nombre de questions | B8: 4 | C8: 10 | D8: 0
A9: Pertinence des questions par rapport au sujet | B9: 10 | C9: 10 | D9: 0
A10: Niveau de compréhension du sujet (démontré à travers les questions posées) | B10: 5 | C10: 5 | D10: 1
A11: Collaboration avec le référent pédagogique (qualité des échanges, réactivité) | B11: 5 | C11: 5 | D11: 0
A12: Clarté et organisation du document PDF (présentation, structure) | B12: 5 | C12: 5 | D12: 1
A13: Originalité et profondeur des questions posées (questions qui démontrent une réflexion approfondie sur le sujet) | B13: 3 | C13: 3 | D13: 0
A14: Qualité de la formulation et absence d'ambiguïté dans les questions | B14: 2 | C14: 2 | D14: 0
A16: Total : 50 points | B16: =SUM(B7:B14) -> 39
A17: Rendu sur l’évaluation du bloc 1 « Management de projet et d'équipes ». | B17: 0.5
A19: Deuxième rendu : Planification du projet (N+3 MOIS)
A21: Critères d'évaluation | B21: Points | C21: Points MAX
A22: Cohérence de la planification globale (adéquation des étapes aux objectifs) | B22: 10 | C22: 10 | D22: 1
A23: Décomposition des tâches en sous-tâches détaillées (conception, développement, tests, déploiement) | B23: 10 | C23: 10 | D23: 1
A24: Clarté et précision du calendrier (dates de début, fin, durée des tâches) | B24: 10 | C24: 10 | D24: 1
A25: Gestion des dépendances entre les tâches (identification et gestion des relations entre les tâches) | B25: 5 | C25: 5 | D25: 1
A26: Gestion des risques identifiés (identification, évaluation et stratégies de mitigation) | B26: 5 | C26: 5 | D26: 1
A27: Utilisation d'outils de planification (diagramme de Gantt ou autre outil pertinent) | B27: 5 | C27: 5 | D27: 2
A28: Inclusion de jalons clés (milestones) pour valider les étapes importantes du projet | B28: 5 | C28: 5 | D28: 1
B29: 0 | C29: 0 | D29: 1
A31: Total : 50 points | B31: =SUM(B22:B29) -> 50 | C31: =SUM(C22:C29) -> 50
A32: Rendu sur l’évaluation du bloc 1 « Management de projet et d'équipes ». | B32: 0.5
A33: Troisième rendu : Soutenance & démo du projet - MVP (N+6 MOIS)
A36: Critères d'évaluation | B36: Points | C36: Points MAX
A37: Clarté de la présentation orale (structure, fluidité, pertinence des informations) | B37: 10 | C37: 10 | D37: 1
A38: Contexte et objectifs du projet : Le groupe présente clairement sa compréhension globale du projet et expose les axes choisis pour traiter l’ensemble des enjeux. | B38: 10 | C38: 10 | D38: 1
A39: Qualité de la démonstration du MVP (fonctionnalités opérationnelles, adéquation aux attentes du projet) | B39: 10 | C39: 10 | D39: 3
A40: Qualité visuelle et technique de la vidéo utilisée pour la démonstration MVP | B40: 5 | C40: 5 | D40: 1
A41: Pertinence des perspectives d’évolution proposées pour le projet futur | B41: 5 | C41: 5 | D41: 2
A42: Originalité des solutions proposées dans le MVP (innovation par rapport aux standards du marché ou aux attentes initiales) | B42: 5 | C42: 5 | D42: 2
A43: Impact potentiel du MVP : Capacité du projet à convaincre les utilisateurs finaux en répondant aux besoins réels. | B43: 5 | C43: 5 | D43: 2
A44: Aller plus loin que l'attendu : Capacité du projet à dépasser les attentes initiales et apporter une valeur ajoutée supplémentaire.
A45: Point Bonus de présentation individuelle
A46: Total : 50 points | B46: =SUM(B36:B45) -> 50 | C46: =SUM(C37:C45) -> 50
A47: % du Rendu sur l’évaluation du bloc 2 « Management, supervision et sécurisation des systèmes d’information ». | B47: 0.3
A49: Quatrième rendu : Livrable final (N+6 MOIS)
...

Sheet LISTE ETUDIANT
A1: Nom | B1: Prénom | C1: Nom complêt | D1: Campus | E1: Groupe de formation
A2: ABAAKIL | B2: Mariya | C2: =_xlfn.CONCAT(A2, " ",B2) -> ABAAKIL Mariya | D2: Paris | E2: MSI 4-26 DEV ISI PARIS | G2: ACHOUR | H2: Sarah | I2: ACHOUR Sarah | J2: Paris | K2: MSI 4-26 BD ISI PARIS
A3: ABBADI | B3: RYAN | C3: =_xlfn.CONCAT(A3, " ",B3) -> ABBADI RYAN | D3: Paris | E3: MSI 4-26 PO ISI PARIS | G3: ADOUKEDJA PETTRO | H3: Steven-Espoir | I3: ADOUKEDJA PETTRO Steven-Espoir | J3: Paris | K3: MSI 4-26 BD ISI PARIS
A4: ABDOU | B4: El Amine | C4: =_xlfn.CONCAT(A4, " ",B4) -> ABDOU El Amine | D4: Paris | E4: MSI 5-25 CS E ISI PARIS | G4: ALITI | H4: Syrine | I4: ALITI Syrine | J4: Paris | K4: MSI 4-26 BD ISI PARIS
A5: ABDULLAH | B5: Gudoos | C5: =_xlfn.CONCAT(A5, " ",B5) -> ABDULLAH Gudoos | D5: Paris | E5: CPI-3-25 SR D ISI PARIS | G5: ALTUNEL | H5: Huseyin-Bora | I5: ALTUNEL Huseyin-Bora | J5: Paris | K5: MSI 4-26 BD ISI PARIS
A6: ABIDAR | B6: Younes | C6: =_xlfn.CONCAT(A6, " ",B6) -> ABIDAR Younes | D6: Paris | E6: CPI-3-25 SR C ISI PARIS | G6: BELKACEMI | H6: Cylia | I6: BELKACEMI Cylia | J6: Paris | K6: MSI 4-26 BD ISI PARIS
A7: ABIRAM | B7: Raveendran | C7: =_xlfn.CONCAT(A7, " ",B7) -> ABIRAM Raveendran | D7: Paris | E7: CPI-3-25 SR C ISI PARIS | G7: BENAMER | H7: Aymen | I7: BENAMER Aymen | J7: Paris | K7: MSI 4-26 BD ISI PARIS
A8: ABOU TOIHIRY | B8: Houssain | C8: =_xlfn.CONCAT(A8, " ",B8) -> ABOU TOIHIRY Houssain | D8: Paris | E8: CPI-2-26 A ISI PARIS | G8: BREVILLE | H8: Alexandre | I8: BREVILLE Alexandre | J8: Paris | K8: MSI 4-26 BD ISI PARIS
A9: ABRAHAM | B9: Lucas | C9: =_xlfn.CONCAT(A9, " ",B9) -> ABRAHAM Lucas | D9: Paris | E9: CPI-2-26 C ISI PARIS | G9: CONDUCHE | H9: Thomas | I9: CONDUCHE Thomas | J9: Paris | K9: MSI 4-26 BD ISI PARIS
A10: ACERBIS | B10: Loris | C10: =_xlfn.CONCAT(A10, " ",B10) -> ACERBIS Loris | D10: Paris | E10: CPI 3-25 SR B ISI PARIS | G10: DANTU | H10: Nathan | I10: DANTU Nathan | J10: Paris | K10: MSI 4-26 BD ISI PARIS
A11: ACHOUR | B11: Sarah | C11: =_xlfn.CONCAT(A11, " ",B11) -> ACHOUR Sarah | D11: Paris | E11: MSI 4-26 BD ISI PARIS | G11: GHANDRICHE | H11: Yani | I11: GHANDRICHE Yani | J11: Paris | K11: MSI 4-26 BD ISI PARIS
A12: ACOINE | B12: Mounir | C12: =_xlfn.CONCAT(A12, " ",B12) -> ACOINE Mounir | D12: Paris | E12: CPI 3-25 SR A ISI PARIS | G12: HACHANI | H12: WAIL | I12: HACHANI WAIL | J12: Paris | K12: MSI 4-26 BD ISI PARIS
A13: ADA | B13: Emile Junior | C13: =_xlfn.CONCAT(A13, " ",B13) -> ADA Emile Junior | D13: Paris | E13: MSI 4-26 DEV ISI PARIS | G13: JEANNEY | H13: Antoine | I13: JEANNEY Antoine | J13: Paris | K13: MSI 4-26 BD ISI PARIS
... A29: ALBAYRAK | B29: Mikail | C29: =_xlfn.CONCAT(A29, " ",B29) -> ALBAYRAK Mikail | D29: Paris | E29: MSI 5-25 CS C ISI PARIS | G29: ZERFAOUI | H29: MEHDI | I29: ZERFAOUI MEHDI | J29: Paris | K29: MSI 4-26 BD ISI PARIS
A30: ALERTE | B30: Benjamin | C30: =_xlfn.CONCAT(A30, " ",B30) -> ALERTE Benjamin | D30: Paris | E30: CPI-1-27 B ISI PARIS
A31: ALIKER | B31: Quentin | C31: =_xlfn.CONCAT(A31, " ",B31) -> ALIKER Quentin | D31: Paris | E31: MSI 4-26 DEV ISI PARIS
A32: ALITI | B32: Syrine | C32: =_xlfn.CONCAT(A32, " ",B32) -> ALITI Syrine | D32: Paris | E32: MSI 4-26 BD ISI PARIS
A33: ALLEM | B33: Akli | C33: =_xlfn.CONCAT(A33, " ",B33) -> ALLEM Akli | D33: Paris | E33: CPI 3-25 SR A ISI PARIS
A34: ALLIOUI | B34: Meriem | C34: =_xlfn.CONCAT(A34, " ",B34) -> ALLIOUI Meriem | D34: Paris | E34: MSI 4-26 CS A ISI PARIS
A35: ALTUNEL | B35: Huseyin-Bora | C35: =_xlfn.CONCAT(A35, " ",B35) -> ALTUNEL Huseyin-Bora | D35: Paris | E35: MSI 4-26 BD ISI PARIS
A36: AMARA | B36: Bilal | C36: =_xlfn.CONCAT(A36, " ",B36) -> AMARA Bilal | D36: Paris | E36: MSI 5-25 CS C ISI PARIS
A37: AMRAOUI | B37: Achraf | C37: =_xlfn.CONCAT(A37, " ",B37) -> AMRAOUI Achraf | D37: Paris | E37: MSI 5-25 CS D ISI PARIS
A38: AMROUCHE | B38: Fatima | C38: =_xlfn.CONCAT(A38, " ",B38) -> AMROUCHE Fatima | D38: Paris | E38: CPI 3-25 DEV B ISI PARIS
A39: ANDRECK | B39: Thomas | C39: =_xlfn.CONCAT(A39, " ",B39) -> ANDRECK Thomas | D39: Paris | E39: CPI-1-27 B ISI PARIS
A40: ANDRIAMIHAJA | B40: Rhidine | C40: =_xlfn.CONCAT(A40, " ",B40) -> ANDRIAMIHAJA Rhidine | D40: Paris | E40: MSI 5-25 PO ISI PARIS
A41: ANG | B41: Gian | C41: =_xlfn.CONCAT(A41, " ",B41) -> ANG Gian | D41: Paris | E41: MSI 5-25 CS B ISI PARIS
... A765: ZUKOWSKI | B765: Richard | C765: =_xlfn.CONCAT(A765, " ",B765) -> ZUKOWSKI Richard | D765: Paris | E765: MSI 5-25 DEV A ISI PARIS

Sheet CLASSE
A1: {=_xlfn._xlws.SORT(_xlfn.UNIQUE('LISTE ETUDIANT'!E2:E685))} -> CPI 3-25 DEV A ISI PARIS | E1: 0
A2: CPI 3-25 DEV B ISI PARIS
A3: CPI 3-25 SR A ISI PARIS
A4: CPI 3-25 SR B ISI PARIS
A5: CPI-1-27 A ISI PARIS
A6: CPI-1-27 B ISI PARIS
A7: CPI-2-26 A ISI PARIS
A8: CPI-2-26 B ISI PARIS
A9: CPI-2-26 C ISI PARIS
A10: CPI-3-25 SR C ISI PARIS
A11: CPI-3-25 SR D ISI PARIS
A12: MSI 4-26 BD ISI PARIS
A13: MSI 4-26 CS A ISI PARIS
... A32: MSI 5-25 PO ISI PARIS
